/**
 * Error scenario testing for all failure categories in troubleshooting guide.
 * Tests analytics collection behavior during various failure modes.
 */

import {beforeEach, describe, expect, test, vi} from 'vitest'
import {createMockSuite} from './mocks/index.js'
import type {FailureCategory, FailureMetrics} from '../src/models.js'

describe('Error Scenario Testing', () => {
  let mocks: ReturnType<typeof createMockSuite>

  beforeEach(() => {
    mocks = createMockSuite()
  })

  describe('GitHub API Failures', () => {
    test('should handle authentication failures', async () => {
      mocks.githubApi.setErrorMode(true)

      const failureMetrics: FailureMetrics = {
        category: 'authentication',
        type: 'github_app_auth_failed',
        message: 'GitHub App authentication failed',
        timestamp: new Date().toISOString(),
        component: 'api',
        recoverable: true,
        retryAttempts: 2,
        context: {
          appId: 'test-app-id',
          repository: 'test/repo',
        },
        stackTrace: 'Error: GitHub App authentication failed',
      }

      expect(failureMetrics.category).toBe('authentication')
      expect(failureMetrics.component).toBe('api')
      expect(failureMetrics.recoverable).toBe(true)
      expect(failureMetrics.retryAttempts).toBe(2)
    })

    test('should handle rate limiting scenarios', async () => {
      mocks.githubApi.setRateLimit(0) // No remaining rate limit

      const rateLimit = await mocks.githubApi.getRateLimit()

      const failureMetrics: FailureMetrics = {
        category: 'api-limits',
        type: 'rate_limit_exceeded',
        message: 'GitHub API rate limit exceeded',
        timestamp: new Date().toISOString(),
        component: 'api',
        recoverable: true,
        retryAttempts: 0,
        context: {
          remaining: rateLimit.remaining,
          limit: rateLimit.limit,
          resetAt: rateLimit.resetAt,
        },
      }

      expect(failureMetrics.category).toBe('api-limits')
      expect(failureMetrics.context?.remaining).toBe(0)
      expect(failureMetrics.recoverable).toBe(true)
    })

    test('should handle token permission issues', async () => {
      const failureMetrics: FailureMetrics = {
        category: 'permissions',
        type: 'insufficient_token_permissions',
        message: 'Insufficient permissions for repository access',
        timestamp: new Date().toISOString(),
        component: 'api',
        recoverable: false,
        context: {
          repository: 'test/private-repo',
          requiredPermissions: ['contents:read', 'metadata:read'],
          actualPermissions: ['metadata:read'],
        },
        stackTrace: 'Error: 403 Forbidden',
      }

      expect(failureMetrics.category).toBe('permissions')
      expect(failureMetrics.component).toBe('api')
      expect(failureMetrics.recoverable).toBe(false)
    })
  })

  describe('Docker Operation Failures', () => {
    test('should handle container execution failures', async () => {
      mocks.dockerOps.setErrorMode(true)

      const failureMetrics: FailureMetrics = {
        category: 'docker-issues',
        type: 'container_execution_failed',
        message: 'Container execution failed for image: renovate/renovate',
        timestamp: new Date().toISOString(),
        component: 'docker',
        recoverable: true,
        retryAttempts: 1,
        context: {
          image: 'renovate/renovate:latest',
          command: ['renovate', '--dry-run'],
          exitCode: 1,
        },
        stackTrace: 'Error: Container execution failed',
      }

      expect(failureMetrics.category).toBe('docker-issues')
      expect(failureMetrics.context?.exitCode).toBe(1)
      expect(failureMetrics.component).toBe('docker')
    })

    test('should handle image pull failures', async () => {
      mocks.dockerOps.setErrorMode(true)

      try {
        await mocks.dockerOps.pullImage('renovate/renovate:invalid-tag')
      } catch (error) {
        const failureMetrics: FailureMetrics = {
          category: 'docker-issues',
          type: 'image_pull_failed',
          message: (error as Error).message,
          timestamp: new Date().toISOString(),
          component: 'docker',
          recoverable: true,
          retryAttempts: 2,
          context: {
            image: 'renovate/renovate:invalid-tag',
            registry: 'docker.io',
          },
          stackTrace: (error as Error).stack || '',
        }

        expect(failureMetrics.category).toBe('docker-issues')
        expect(failureMetrics.context?.image).toContain('invalid-tag')
        expect(failureMetrics.recoverable).toBe(true)
      }
    })

    test('should handle tool installation failures', async () => {
      mocks.dockerOps.setErrorMode(true)

      try {
        await mocks.dockerOps.installTool('invalid-tool', '1.0.0')
      } catch (error) {
        const failureMetrics: FailureMetrics = {
          category: 'docker-issues',
          type: 'tool_installation_failed',
          message: (error as Error).message,
          timestamp: new Date().toISOString(),
          component: 'docker',
          recoverable: true,
          retryAttempts: 1,
          context: {
            tool: 'invalid-tool',
            version: '1.0.0',
            packageManager: 'npm',
          },
          stackTrace: (error as Error).stack || '',
        }

        expect(failureMetrics.category).toBe('docker-issues')
        expect(failureMetrics.type).toBe('tool_installation_failed')
        expect(failureMetrics.recoverable).toBe(true)
      }
    })
  })

  describe('Cache Operation Failures', () => {
    test('should handle cache corruption scenarios', async () => {
      mocks.cacheOps.setErrorMode(true)

      try {
        await mocks.cacheOps.restore('corrupted-cache-key')
      } catch (error) {
        const failureMetrics: FailureMetrics = {
          category: 'cache-corruption',
          type: 'cache_restore_failed',
          message: (error as Error).message,
          timestamp: new Date().toISOString(),
          component: 'cache',
          recoverable: true,
          retryAttempts: 1,
          context: {
            cacheKey: 'corrupted-cache-key',
            operation: 'restore',
          },
          stackTrace: (error as Error).stack || '',
        }

        expect(failureMetrics.category).toBe('cache-corruption')
        expect(failureMetrics.context?.operation).toBe('restore')
        expect(failureMetrics.component).toBe('cache')
      }
    })

    test('should handle cache storage quota exceeded', async () => {
      // Simulate cache quota exceeded scenario
      const failureMetrics: FailureMetrics = {
        category: 'cache-corruption',
        type: 'cache_quota_exceeded',
        message: 'GitHub Actions cache quota exceeded (10GB limit)',
        timestamp: new Date().toISOString(),
        component: 'cache',
        recoverable: true,
        retryAttempts: 0,
        context: {
          currentSize: 10_737_418_240, // 10GB in bytes
          limit: 10_737_418_240,
          operation: 'save',
        },
      }

      expect(failureMetrics.category).toBe('cache-corruption')
      expect(failureMetrics.context?.currentSize).toBe(failureMetrics.context?.limit)
      expect(failureMetrics.component).toBe('cache')
    })

    test('should handle cache API failures', async () => {
      mocks.cacheOps.setErrorMode(true)

      try {
        await mocks.cacheOps.save('test-key', {data: 'test'})
      } catch (error) {
        const failureMetrics: FailureMetrics = {
          category: 'api-limits',
          type: 'cache_api_failed',
          message: (error as Error).message,
          timestamp: new Date().toISOString(),
          component: 'cache',
          recoverable: true,
          retryAttempts: 2,
          context: {
            operation: 'save',
            cacheKey: 'test-key',
            apiEndpoint: 'https://api.github.com/repos/owner/repo/actions/caches',
          },
          stackTrace: (error as Error).stack || '',
        }

        expect(failureMetrics.category).toBe('api-limits')
        expect(failureMetrics.component).toBe('cache')
        expect(failureMetrics.recoverable).toBe(true)
      }
    })
  })

  describe('Network Connectivity Failures', () => {
    test('should handle network timeout scenarios', async () => {
      mocks.network.setErrorMode(true)

      try {
        await mocks.network.fetch('https://api.github.com/repos/test/repo')
      } catch (error) {
        const failureMetrics: FailureMetrics = {
          category: 'timeout',
          type: 'network_timeout',
          message: (error as Error).message,
          timestamp: new Date().toISOString(),
          component: 'api',
          recoverable: true,
          retryAttempts: 3,
          context: {
            url: 'https://api.github.com/repos/test/repo',
            timeout: 5000,
            retryAttempt: 1,
          },
          stackTrace: (error as Error).stack || '',
        }

        expect(failureMetrics.category).toBe('timeout')
        expect(failureMetrics.context?.timeout).toBe(5000)
        expect(failureMetrics.recoverable).toBe(true)
      }
    })

    test('should handle DNS resolution failures', async () => {
      mocks.network.setErrorMode(true)

      const failureMetrics: FailureMetrics = {
        category: 'network-issues',
        type: 'dns_resolution_failed',
        message: 'DNS resolution failed for api.github.com',
        timestamp: new Date().toISOString(),
        component: 'api',
        recoverable: false,
        context: {
          hostname: 'api.github.com',
          dnsServers: ['8.8.8.8', '1.1.1.1'],
        },
        stackTrace: 'Error: DNS resolution failed',
      }

      expect(failureMetrics.category).toBe('network-issues')
      expect(failureMetrics.context?.hostname).toBe('api.github.com')
      expect(failureMetrics.recoverable).toBe(false)
    })

    test('should handle SSL certificate issues', async () => {
      const failureMetrics: FailureMetrics = {
        category: 'network-issues',
        type: 'ssl_certificate_error',
        message: 'SSL certificate verification failed',
        timestamp: new Date().toISOString(),
        component: 'api',
        recoverable: false,
        context: {
          hostname: 'expired-ssl-site.com',
          certificateError: 'certificate has expired',
        },
        stackTrace: 'Error: SSL certificate verification failed',
      }

      expect(failureMetrics.category).toBe('network-issues')
      expect(failureMetrics.component).toBe('api')
      expect(failureMetrics.recoverable).toBe(false)
    })
  })

  describe('Configuration and Input Failures', () => {
    test('should handle invalid configuration scenarios', async () => {
      const failureMetrics: FailureMetrics = {
        category: 'configuration-error',
        type: 'invalid_renovate_config',
        message: 'Invalid Renovate configuration detected',
        timestamp: new Date().toISOString(),
        component: 'config',
        recoverable: true,
        context: {
          configFile: '.github/renovate.json5',
          validationErrors: [
            'Property "schedule" should be array',
            'Unknown property "invalidProperty"',
          ],
        },
      }

      expect(failureMetrics.category).toBe('configuration-error')
      expect((failureMetrics.context?.validationErrors as string[]).length).toBe(2)
      expect(failureMetrics.component).toBe('config')
    })

    test('should handle missing required inputs', async () => {
      const failureMetrics: FailureMetrics = {
        category: 'configuration-error',
        type: 'missing_required_inputs',
        message: 'Required input "renovate-app-id" is missing',
        timestamp: new Date().toISOString(),
        component: 'action',
        recoverable: false,
        context: {
          missingInputs: ['renovate-app-id', 'renovate-app-private-key'],
          providedInputs: ['log-level', 'dry-run'],
        },
      }

      expect(failureMetrics.category).toBe('configuration-error')
      expect((failureMetrics.context?.missingInputs as string[]).includes('renovate-app-id')).toBe(true)
      expect(failureMetrics.recoverable).toBe(false)
    })
  })

  describe('Repository Access Failures', () => {
    test('should handle repository not found scenarios', async () => {
      mocks.githubApi.setErrorMode(true)

      try {
        await mocks.githubApi.getRepository('nonexistent', 'repo')
      } catch (error) {
        const failureMetrics: FailureMetrics = {
          category: 'permissions',
          type: 'repository_not_found',
          message: (error as Error).message,
          timestamp: new Date().toISOString(),
          component: 'api',
          recoverable: false,
          context: {
            repository: 'nonexistent/repo',
            httpStatus: 404,
          },
          stackTrace: (error as Error).stack || '',
        }

        expect(failureMetrics.category).toBe('permissions')
        expect(failureMetrics.context?.httpStatus).toBe(404)
        expect(failureMetrics.recoverable).toBe(false)
      }
    })

    test('should handle private repository access denied', async () => {
      const failureMetrics: FailureMetrics = {
        category: 'permissions',
        type: 'repository_access_denied',
        message: 'Access denied to private repository',
        timestamp: new Date().toISOString(),
        component: 'api',
        recoverable: false,
        context: {
          repository: 'private-org/private-repo',
          httpStatus: 403,
          requiredPermissions: ['contents:read'],
        },
        stackTrace: 'Error: 403 Forbidden',
      }

      expect(failureMetrics.category).toBe('permissions')
      expect(failureMetrics.context?.httpStatus).toBe(403)
      expect(failureMetrics.recoverable).toBe(false)
    })
  })

  describe('Resource Limitation Failures', () => {
    test('should handle memory exhaustion scenarios', async () => {
      const failureMetrics: FailureMetrics = {
        category: 'unknown',
        type: 'memory_exhaustion',
        message: 'Out of memory during analytics processing',
        timestamp: new Date().toISOString(),
        component: 'action',
        recoverable: true,
        retryAttempts: 1,
        context: {
          memoryUsage: {
            heapUsed: 4_294_967_296, // 4GB
            heapTotal: 4_294_967_296,
            external: 1_073_741_824, // 1GB
          },
          availableMemory: 7_516_192_768, // 7GB
        },
        stackTrace: 'Error: JavaScript heap out of memory',
      }

      expect(failureMetrics.category).toBe('unknown')
      expect(failureMetrics.type).toBe('memory_exhaustion')
      expect(failureMetrics.recoverable).toBe(true)
    })

    test('should handle disk space exhaustion', async () => {
      const failureMetrics: FailureMetrics = {
        category: 'unknown',
        type: 'disk_space_exhaustion',
        message: 'Insufficient disk space for cache operations',
        timestamp: new Date().toISOString(),
        component: 'cache',
        recoverable: true,
        retryAttempts: 1,
        context: {
          availableSpace: 1_073_741_824, // 1GB
          requiredSpace: 5_368_709_120, // 5GB
          diskUsage: '95%',
        },
        stackTrace: 'Error: ENOSPC: no space left on device',
      }

      expect(failureMetrics.category).toBe('unknown')
      expect(failureMetrics.type).toBe('disk_space_exhaustion')
      expect(failureMetrics.recoverable).toBe(true)
    })
  })

  describe('Graceful Degradation Testing', () => {
    test('should continue operation when analytics collection fails', async () => {
      // Simulate analytics failure but main operation should continue
      const analyticsEnabled = false
      const mainOperationResult = {success: true, message: 'Renovate completed successfully'}

      // Even if analytics fails, main operation should not be affected
      expect(mainOperationResult.success).toBe(true)
      expect(analyticsEnabled).toBe(false)
    })

    test('should provide meaningful error messages for debugging', async () => {
      const failureMetrics: FailureMetrics = {
        category: 'unknown',
        type: 'analytics_collection_failed',
        message: 'Analytics collection failed but operation continued',
        timestamp: new Date().toISOString(),
        component: 'action',
        recoverable: true,
        context: {
          analyticsEnabled: true,
          collectionStep: 'cache_metrics',
          originalError: 'Failed to save analytics data to cache',
        },
        stackTrace: 'Error in analytics collection',
      }

      expect(failureMetrics.category).toBe('unknown')
      expect(failureMetrics.type).toBe('analytics_collection_failed')
      expect(failureMetrics.recoverable).toBe(true)
    })
  })

  describe('Error Recovery Validation', () => {
    test('should validate retry mechanisms work correctly', async () => {
      let attemptCount = 0
      const maxRetries = 3

      const retryOperation = async (): Promise<boolean> => {
        attemptCount++
        if (attemptCount < maxRetries) {
          throw new Error(`Attempt ${attemptCount} failed`)
        }
        return true
      }

      let lastError: Error | null = null
      let success = false

      for (let i = 0; i < maxRetries; i++) {
        try {
          success = await retryOperation()
          break
        } catch (error) {
          lastError = error as Error
          // Wait before retry (exponential backoff simulation)
          await new Promise(resolve => setTimeout(resolve, Math.pow(2, i) * 10)) // Reduced delay for tests
        }
      }

      expect(success).toBe(true)
      expect(attemptCount).toBe(maxRetries)
      expect(lastError?.message).toBe('Attempt 2 failed')
    })

    test('should validate fallback strategies are effective', async () => {
      const primaryStrategy = async (): Promise<string> => {
        throw new Error('Primary strategy failed')
      }

      const fallbackStrategy = async (): Promise<string> => {
        return 'Fallback successful'
      }

      let result: string
      try {
        result = await primaryStrategy()
      } catch {
        result = await fallbackStrategy()
      }

      expect(result).toBe('Fallback successful')
    })
  })
})
